Workbook

Sheet Sheet1
B6: BẢNG CHẤM CÔNG THÁNG | D6: 6 | E6: Năm | F6: 2022
A7: 1 | B7: 2 | C7: 3 | E7: 5 | F7: 6 | G7: 7 | H7: 8 | I7: 9 | J7: 10 | K7: 11 | L7: 12 | M7: 13 | N7: 14 | O7: 15 | P7: 16 | Q7: 17 | R7: 18 | S7: 19 | T7: 20 | U7: 21 | V7: 22 | W7: 23 | X7: 24 | Y7: 25 | Z7: 26 | AA7: 27 | AB7: 28 | AC7: 29 | AD7: 30 | AE7: 31 | AF7: 32 | AG7: 33 | AH7: 34 | AI7: 35 | AJ7: 36 | AK7: 37 | AL7: 38 | AM7: 39 | AN7: 40 | AO7: 41 | AP7: 42 | AQ7: 43 | AR7: 44 | AS7: 45 | AT7: 46 | AU7: 47 | AV7: 48 | AW7: 49 | AX7: 50 | AY7: 51 | AZ7: 52 | BA7: 53 | BB7: 54 | BC7: 55 | BD7: 56 | BE7: 57 | BF7: 58 | BG7: 59 | BH7: 60 | BI7: 61 | BJ7: 62 | BK7: 63 | BL7: 64 | BM7: 65 | BN7: 66 | BO7: 67 | BP7: 68 | BQ7: 69 | BR7: 70 | BS7: 71 | BT7: 72 | BU7: 73 | BV7: 74 | BW7: 75 | BX7: 76
A8: Mã số | B8: Họ và tên | C8: Bộ phận | D8: Khối làm việc | E8: Ngày nhận việc | F8: Ngày phép còn lại đầu tháng 05 | G8: =DATE(F6,D6,1) | I8: =G8+1 | K8: =I8+1 | M8: =K8+1 | O8: =M8+1 | Q8: =O8+1 | S8: =Q8+1 | U8: =S8+1 | W8: =U8+1 | Y8: =W8+1 | AA8: =Y8+1 | AC8: =AA8+1 | AE8: =AC8+1 | AG8: =AE8+1 | AI8: =AG8+1 | AK8: =AI8+1 | AM8: =AK8+1 | AO8: =AM8+1 | AQ8: =AO8+1 | AS8: =AQ8+1 | AU8: =AS8+1 | AW8: =AU8+1 | AY8: =AW8+1 | BA8: =AY8+1 | BC8: =BA8+1 | BE8: =BC8+1 | BG8: =BE8+1 | BI8: =IF(BG8="","",IF(BG8=EOMONTH(DATE($F$6,$D$6,1),0),"",BG8+1)) | BK8: =IF(BI8="","",IF(BI8=EOMONTH(DATE($F$6,$D$6,1),0),"",BI8+1)) | BM8: =IF(BK8="","",IF(BK8=EOMONTH(DATE($F$6,$D$6,1),0),"",BK8+1)) | BO8: =IF(BM8="","",IF(BM8=EOMONTH(DATE($F$6,$D$6,1),0),"",BM8+1)) | BQ8: Tổng thời gian vào trể | BR8: Tổng ngày vào trể | BS8: Tổng giờ về sớm | BT8: Tổng ngày về sớm | BU8: Tổng ngày nghỉ | BV8: Quên chấm công vào | BW8: Quên chấm công ra | BX8: Tổng quên chấm công
G9: Đi trể | H9: Về sớm | I9: Đi trể | J9: Về sớm | K9: Đi trể | L9: Về sớm | M9: Đi trể | N9: Về sớm | O9: Đi trể | P9: Về sớm | Q9: Đi trể | R9: Về sớm | S9: Đi trể | T9: Về sớm | U9: Đi trể | V9: Về sớm | W9: Đi trể | X9: Về sớm | Y9: Đi trể | Z9: Về sớm | AA9: Đi trể | AB9: Về sớm | AC9: Đi trể | AD9: Về sớm | AE9: Đi trể | AF9: Về sớm | AG9: Đi trể | AH9: Về sớm | AI9: Đi trể | AJ9: Về sớm | AK9: Đi trể | AL9: Về sớm | AM9: Đi trể | AN9: Về sớm | AO9: Đi trể | AP9: Về sớm | AQ9: Đi trể | AR9: Về sớm | AS9: Đi trể | AT9: Về sớm | AU9: Đi trể | AV9: Về sớm | AW9: Đi trể | AX9: Về sớm | AY9: Đi trể | AZ9: Về sớm | BA9: Đi trể | BB9: Về sớm | BC9: Đi trể | BD9: Về sớm | BE9: Đi trể | BF9: Về sớm | BG9: Đi trể | BH9: Về sớm | BI9: Đi trể | BJ9: Về sớm | BK9: Đi trể | BL9: Về sớm | BM9: Đi trể | BN9: Về sớm | BO9: Đi trể | BP9: Về sớm
A11: A001 | B11: Tống Viết Cường | C11: BAN GIÁM ĐỐC | D11: Gián tiếp | E11: 2004-01-01 | G11: Nghi | I11: Nghi | K11: Nghi | M11: Nghi | Q11: Nghi | S11: Nghi | U11: Nghi | W11: Nghi | Y11: Nghi | AA11: Nghi | AE11: Nghi | AG11: Nghi | AI11: Nghi | AK11: Nghi | AM11: Nghi | AO11: Nghi | AS11: Nghi | AU11: Nghi | AW11: Nghi | AY11: Nghi | BA11: Nghi | BC11: Nghi | BG11: Nghi | BI11: Nghi | BK11: Nghi | BM11: Nghi
A12: A003 | B12: Tống Phước Tiến | C12: MUA HÀNG | D12: Gián tiếp | E12: 2004-01-01 | G12: Nghi | I12: Nghi | K12: Nghi | M12: Nghi | Q12: Nghi | S12: Nghi | U12: Nghi | W12: Nghi | Y12: Nghi | AA12: Nghi | AE12: Nghi | AG12: Nghi | AI12: Nghi | AK12: Nghi | AM12: Nghi | AO12: Nghi | AS12: Nghi | AU12: Nghi | AW12: Nghi | AY12: Nghi | BA12: Nghi | BC12: Nghi | BG12: Nghi | BI12: Nghi | BK12: Nghi | BM12: Nghi
A13: A007 | B13: Đào Thanh Điền | C13: X2 Line 2-1 | D13: Trực tiếp | E13: 2005-02-01 | T13: 91 | AP13: 3 | AS13: Nghi | AU13: Nghi | AW13: Nghi | AY13: Nghi | BA13: Nghi | BC13: Nghi | BG13: Nghi | BL13: 55
A14: A010 | B14: Dương Khánh Linh | C14: MUA HÀNG | D14: Gián tiếp | E14: 2005-03-01 | M14: Nghi | AB14: QCC | AM14: Nghi | AO14: Nghi | AS14: Nghi | BC14: Nghi
A15: A015 | B15: Nguyễn Văn Năm | C15: X2 Line 2-4 | D15: Trực tiếp | E15: 2005-04-04 | P15: 59 | Y15: Nghi | AT15: QCC | BE15: 240
A16: A021 | B16: Cao Thị Kim Thu | C16: QA/QC X1 Ép | D16: Trực tiếp | E16: 2006-04-04 | O16: Nghi | AS16: Nghi | AY16: Nghi
A17: A023 | B17: Nguyễn Văn Mừng | C17: X1 Xi Line 1-1 | D17: Trực tiếp | E17: 2006-08-01 | M17: Nghi | AB17: 238 | AO17: Nghi | AS17: Nghi | AU17: Nghi
A18: A027 | B18: Đỗ Tấn Lạnh | C18: X2 Line 2-1 | D18: Trực tiếp | E18: 2007-07-02 | N18: 236 | AK18: Nghi | AS18: Nghi | AV18: QCC | BF18: 60
A19: A028 | B19: Nguyễn Trung Lập | C19: X2 Line 2-2 | D19: Trực tiếp | E19: 2007-07-09 | AH19: 115 | AS19: Nghi | BG19: Nghi | BI19: Nghi
A20: A030 | B20: Phạm Tấn Minh | C20: X2 Line 2-2 | D20: Trực tiếp | E20: 2007-10-05 | R20: 58 | AO20: Nghi | AS20: Nghi | BB20: QCC | BD20: 54
A21: A032 | B21: Lý Tuệ Vân | C21: Kế Toán Tài Chính | D21: Gián tiếp | E21: 2008-03-01 | M21: QCC | N21: 25 | Y21: QCC | AA21: Nghi | AJ21: 123 | AK21: Nghi | AM21: Nghi | AO21: Nghi | AS21: 32 | AT21: 16 | BD21: 26
A22: A033 | B22: Hà Công Hoàng Minh | C22: X2 Line 2-1 | D22: Trực tiếp | E22: 2008-03-13 | G22: Nghi | I22: 57 | AE22: 55 | AG22: 58 | AI22: Nghi | AK22: 60 | AM22: 54 | AS22: Nghi | AU22: Nghi
A23: A042 | B23: Phạm Hoàng Khanh | C23: R&D | D23: Gián tiếp | E23: 2009-02-23 | I23: Nghi | M23: Nghi | S23: 286 | AA23: Nghi | AF23: QCC | AG23: QCC | AH23: 1 | AI23: 248 | AM23: 1 | AS23: Nghi | AU23: 1 | AW23: 72 | AY23: Nghi | BC23: Nghi | BH23: QCC | BI23: 1
A24: A046 | B24: Lê Văn Hà | C24: X2 Line 2-1 | D24: Trực tiếp | E24: 2009-04-07 | L24: 239 | P24: 87 | Y24: 104 | AN24: 238 | AO24: Nghi | AS24: Nghi | AU24: 99 | AV24: 57
A25: A049 | B25: Phạm Tấn Việt | C25: X1 Xi Line 1-1 | D25: Trực tiếp | E25: 2009-04-13 | AA25: Nghi | AS25: Nghi | BD25: 24 | BE25: 240
A26: A055 | B26: Nguyễn Thị Dung Em | C26: X1 Xi Line 1-1 | D26: Trực tiếp | E26: 2009-05-18 | AO26: Nghi | AS26: Nghi | AU26: Nghi
A27: A059 | B27: Ngô Nhật Thanh | C27: X2 Line 2-1 | D27: Trực tiếp | E27: 2009-06-04 | L27: 239 | AP27: 238 | AS27: Nghi | BA27: Nghi
A28: A061 | B28: Đỗ Thị Thanh Thảo | C28: QA/QC X2 | D28: Trực tiếp | E28: 2009-06-05 | H28: 57 | J28: 58 | L28: 58 | N28: 58 | O28: 58 | P28: QCC | R28: 54 | T28: 58 | V28: 59 | X28: 59 | Z28: 57 | AB28: 57 | AF28: 57 | AG28: Nghi | AJ28: 57 | AL28: 150 | AN28: 57 | AO28: Nghi | AS28: Nghi | AV28: 57 | AW28: Nghi | AZ28: 57 | BB28: 58 | BD28: 57 | BE28: 57 | BH28: 56 | BJ28: 59 | BL28: 57 | BM28: 1 | BN28: 57
A29: A068 | B29: Nguyễn Văn Phúc | C29: BT Gia Công | D29: Trực tiếp | E29: 2009-09-07 | H29: 57 | J29: 60 | L29: 60 | N29: 114 | O29: 43 | P29: 56 | R29: 106 | T29: 114 | V29: 86 | X29: 89 | Y29: Nghi | AB29: 59 | AC29: 44 | AD29: 25 | AF29: 58 | AH29: 90 | AJ29: 86 | AL29: 119 | AN29: 118 | AP29: 146 | AQ29: Nghi | AS29: Nghi | AV29: 60 | AX29: 120 | AZ29: 85 | BB29: 59 | BD29: 119 | BE29: 38 | BF29: 88 | BH29: 59 | BI29: 101 | BJ29: 60 | BL29: 59 | BN29: 56
A30: A080 | B30: Trần Minh Thuận | C30: X1 Ép - Nguội | D30: Trực tiếp | E30: 2010-03-31 | AS30: Nghi | BK30: 118 | BL30: 88 | BM30: 120 | BN30: 89
A31: A084 | B31: Trần Kim Thoa | C31: X1 Ép - A | D31: Trực tiếp | E31: 2010-04-20 | G31: 1 | H31: 14 | O31: 240 | AH31: QCC | AO31: Nghi | AS31: Nghi | BG31: Nghi
A32: A086 | B32: Nguyễn Tấn Hưng | C32: BT Gia Công | D32: Trực tiếp | E32: 2010-04-26 | L32: 60 | N32: 59 | P32: 120 | R32: 56 | T32: 60 | V32: 58 | X32: 58 | Z32: 58 | AB32: 120 | AD32: 59 | AL32: 58 | AP32: 120 | AQ32: Nghi | AS32: Nghi | AU32: 45 | AV32: 44 | AZ32: 21 | BD32: 64 | BF32: 60 | BH32: 56 | BJ32: 59 | BL32: 60 | BN32: 60
A33: A087 | B33: Đoàn Văn Cường | C33: X1 Gá | D33: Trực tiếp | E33: 2010-04-26 | AS33: Nghi | BC33: 5
A34: A093 | B34: Trần Văn Đông | C34: X1 Gá | D34: Trực tiếp | E34: 2010-05-14 | AS34: Nghi
A35: A1025 | B35: Phạm Thị Ngọc Ánh | C35: QA/QC Hành Chính | D35: Gián tiếp | E35: 2017-11-27 | K35: 46 | Y35: 2 | AI35: 25 | AS35: Nghi | AW35: 1 | BM35: 3
A36: A1039 | B36: Đặng Văn Pháp | C36: X1 Xi Line 1-1 | D36: Trực tiếp | E36: 2018-02-27 | L36: 180 | AB36: QCC | AS36: Nghi
A37: A105 | B37: Trần Thị Diệp | C37: X1 Ép - B | D37: Trực tiếp | E37: 2010-07-07 | AC37: 240 | AI37: Nghi | AS37: Nghi | BC37: Nghi | BI37: Nghi | BK37: Nghi | BM37: Nghi
A38: A1061 | B38: Võ Minh Kiệt | C38: QA/QC X2 | D38: Trực tiếp | E38: 2018-03-10 | G38: 119 | AD38: QCC | AO38: Nghi | AS38: Nghi | AU38: Nghi | BK38: 246
A39: A1074 | B39: Nguyễn Tuấn Anh | C39: X1 Ép - A | D39: Trực tiếp | E39: 2018-03-01 | G39: 5 | H39: 20 | AK39: Nghi | AO39: Nghi | AS39: Nghi | BM39: Nghi
A40: A1076 | B40: Nguyễn Thành Lâm | C40: QA/QC X2 | D40: Trực tiếp | E40: 2018-04-05 | I40: QCC | M40: Nghi | AS40: Nghi | BC40: Nghi | BJ40: 8
A41: A1083 | B41: Nguyễn Thùy Linh | C41: Nhân Sự | D41: Gián tiếp | E41: 2018-05-18 | H41: QCC | K41: QCC | M41: Nghi | AI41: Nghi | AM41: 2 | AN41: QCC | AO41: Nghi | AS41: Nghi | AU41: 170 | BA41: 131 | BC41: 99 | BD41: 13 | BG41: 202 | BI41: 70 | BN41: 149
A42: A1089 | B42: Thái Khắc Thiện | C42: Khuôn Lập trình-gia công | D42: Gián tiếp | E42: 2018-05-26 | K42: Nghi | M42: Nghi | AS42: Nghi
A43: A1100 | B43: Phạm Thị Trúc Ly | C43: QA/QC X1 Xi | D43: Trực tiếp | E43: 2018-05-10 | L43: 180 | S43: Nghi | AQ43: Nghi | AS43: Nghi | AU43: Nghi
A44: A1109 | B44: Nguyễn Thị Huyền Chân | C44: X1 Xi Line 1-1 | D44: Trực tiếp | E44: 2018-06-20 | AA44: Nghi | AS44: Nghi
A45: A1110 | B45: Nguyễn Hữu Bạc | C45: X1 Xi Line 1-1 | D45: Trực tiếp | E45: 2018-06-20 | G45: Nghi | M45: Nghi | AI45: Nghi | AS45: Nghi | BC45: 17 | BI45: Nghi
A46: A1124 | B46: Ngô Thị Kim Hân | C46: Kho X3 | D46: Trực tiếp | E46: 2018-07-11 | J46: 56 | N46: 57 | O46: 40 | P46: 179 | V46: 57 | Z46: 58 | AB46: 59 | AC46: 43 | AD46: 169 | AJ46: 58 | AN46: 59 | AP46: 116 | AQ46: Nghi | AS46: Nghi | BB46: 56 | BD46: 58 | BE46: 38 | BF46: 180
...

Sheet Sheet2
B6: BẢNG CHẤM CÔNG THÁNG | D6: =IF(Sheet1!D6 <> "",IF(ISNUMBER(VALUE(Sheet1!D6)),VALUE(Sheet1!D6),Sheet1!D6),"") | E6: Năm | F6: =IF(Sheet1!F6 <> "",IF(ISNUMBER(VALUE(Sheet1!F6)),VALUE(Sheet1!F6),Sheet1!F6),"")
A7: 1 | B7: 2 | C7: 3 | E7: 5 | F7: 6 | G7: 7 | H7: 8 | I7: 9 | J7: 10 | K7: 11 | L7: 12 | M7: 13 | N7: 14 | O7: 15 | P7: 16 | Q7: 17 | R7: 18 | S7: 19 | T7: 20 | U7: 21 | V7: 22 | W7: 23 | X7: 24 | Y7: 25 | Z7: 26 | AA7: 27 | AB7: 28 | AC7: 29 | AD7: 30 | AE7: 31 | AF7: 32 | AG7: 33 | AH7: 34 | AI7: 35 | AJ7: 36 | AK7: 37 | AL7: 38 | AM7: 39 | AN7: 40 | AO7: 41 | AP7: 42 | AQ7: 43 | AR7: 44 | AS7: 45 | AT7: 46 | AU7: 47 | AV7: 48 | AW7: 49 | AX7: 50 | AY7: 51 | AZ7: 52 | BA7: 53 | BB7: 54 | BC7: 55 | BD7: 56 | BE7: 57 | BF7: 58 | BG7: 59 | BH7: 60 | BI7: 61 | BJ7: 62 | BK7: 63 | BL7: 64 | BM7: 65 | BN7: 66 | BO7: 67 | BP7: 68 | BQ7: 69 | BR7: 70 | BS7: 71 | BT7: 72 | BU7: 73 | BV7: 74 | BW7: 75 | BX7: 76
A8: Mã số | B8: Họ và tên | C8: Bộ phận | D8: Khối làm việc | E8: Ngày nhận việc | F8: Ngày phép còn lại đầu tháng 05 | G8: =DATE(F6,D6,1) | I8: =G8+1 | K8: =I8+1 | M8: =K8+1 | O8: =M8+1 | Q8: =O8+1 | S8: =Q8+1 | U8: =S8+1 | W8: =U8+1 | Y8: =W8+1 | AA8: =Y8+1 | AC8: =AA8+1 | AE8: =AC8+1 | AG8: =AE8+1 | AI8: =AG8+1 | AK8: =AI8+1 | AM8: =AK8+1 | AO8: =AM8+1 | AQ8: =AO8+1 | AS8: =AQ8+1 | AU8: =AS8+1 | AW8: =AU8+1 | AY8: =AW8+1 | BA8: =AY8+1 | BC8: =BA8+1 | BE8: =BC8+1 | BG8: =BE8+1 | BI8: =IF(BG8="","",IF(BG8=EOMONTH(DATE($F$6,$D$6,1),0),"",BG8+1)) | BK8: =IF(BI8="","",IF(BI8=EOMONTH(DATE($F$6,$D$6,1),0),"",BI8+1)) | BM8: =IF(BK8="","",IF(BK8=EOMONTH(DATE($F$6,$D$6,1),0),"",BK8+1)) | BO8: =IF(BM8="","",IF(BM8=EOMONTH(DATE($F$6,$D$6,1),0),"",BM8+1)) | BQ8: Tổng thời gian vào trể | BR8: Tổng ngày vào trể | BS8: Tổng giờ về sớm | BT8: Tổng ngày về sớm | BU8: Tổng ngày nghỉ | BV8: Quên chấm công vào | BW8: Quên chấm công ra | BX8: Tổng quên chấm công
G9: Đi trể | H9: Về sớm | I9: Đi trể | J9: Về sớm | K9: Đi trể | L9: Về sớm | M9: Đi trể | N9: Về sớm | O9: Đi trể | P9: Về sớm | Q9: Đi trể | R9: Về sớm | S9: Đi trể | T9: Về sớm | U9: Đi trể | V9: Về sớm | W9: Đi trể | X9: Về sớm | Y9: Đi trể | Z9: Về sớm | AA9: Đi trể | AB9: Về sớm | AC9: Đi trể | AD9: Về sớm | AE9: Đi trể | AF9: Về sớm | AG9: Đi trể | AH9: Về sớm | AI9: Đi trể | AJ9: Về sớm | AK9: Đi trể | AL9: Về sớm | AM9: Đi trể | AN9: Về sớm | AO9: Đi trể | AP9: Về sớm | AQ9: Đi trể | AR9: Về sớm | AS9: Đi trể | AT9: Về sớm | AU9: Đi trể | AV9: Về sớm | AW9: Đi trể | AX9: Về sớm | AY9: Đi trể | AZ9: Về sớm | BA9: Đi trể | BB9: Về sớm | BC9: Đi trể | BD9: Về sớm | BE9: Đi trể | BF9: Về sớm | BG9: Đi trể | BH9: Về sớm | BI9: Đi trể | BJ9: Về sớm | BK9: Đi trể | BL9: Về sớm | BM9: Đi trể | BN9: Về sớm | BO9: Đi trể | BP9: Về sớm
A11: =IF(Sheet1!A11 <> "",IF(ISNUMBER(VALUE(Sheet1!A11)),VALUE(Sheet1!A11),Sheet1!A11),"") | B11: =IF(Sheet1!B11 <> "",IF(ISNUMBER(VALUE(Sheet1!B11)),VALUE(Sheet1!B11),Sheet1!B11),"") | C11: =IF(Sheet1!C11 <> "",IF(ISNUMBER(VALUE(Sheet1!C11)),VALUE(Sheet1!C11),Sheet1!C11),"") | D11: =IF(Sheet1!D11 <> "",IF(ISNUMBER(VALUE(Sheet1!D11)),VALUE(Sheet1!D11),Sheet1!D11),"") | E11: =IF(Sheet1!E11 <> "",IF(ISNUMBER(VALUE(Sheet1!E11)),VALUE(Sheet1!E11),Sheet1!E11),"") | F11: =IF(Sheet1!F11 <> "",IF(ISNUMBER(VALUE(Sheet1!F11)),VALUE(Sheet1!F11),Sheet1!F11),"") | G11: =IF(Sheet1!G11 <> "",IF(ISNUMBER(VALUE(Sheet1!G11)),VALUE(Sheet1!G11),Sheet1!G11),"") | H11: =IF(Sheet1!H11 <> "",IF(ISNUMBER(VALUE(Sheet1!H11)),VALUE(Sheet1!H11),Sheet1!H11),"") | ... BP11: =IF(Sheet1!BP11 <> "",IF(ISNUMBER(VALUE(Sheet1!BP11)),VALUE(Sheet1!BP11),Sheet1!BP11),"") | BQ11: =SUMIFS(G11:BP11,$G$9:$BP$9, $BO$9, G11:BP11,">0") | BR11: =COUNTIFS($G$9:$BP$9, $BO$9, G11:BP11,">0") | BS11: =SUMIFS(G11:BP11,$G$9:$BP$9, $BP$9, G11:BP11,">0") | BT11: =COUNTIFS($G$9:$BP$9, $BP$9, G11:BP11,">0") | BU11: =COUNTIF(G11:BP11,"Nghi") | BV11: =COUNTIFS($G$9:$BP$9, $BO$9, G11:BP11,$BX$8) | BW11: =COUNTIFS($G$9:$BP$9, $BP$9, G11:BP11,$BX$8) | BX11: =BV11+BW11
A12: =IF(Sheet1!A12 <> "",IF(ISNUMBER(VALUE(Sheet1!A12)),VALUE(Sheet1!A12),Sheet1!A12),"") | B12: =IF(Sheet1!B12 <> "",IF(ISNUMBER(VALUE(Sheet1!B12)),VALUE(Sheet1!B12),Sheet1!B12),"") | C12: =IF(Sheet1!C12 <> "",IF(ISNUMBER(VALUE(Sheet1!C12)),VALUE(Sheet1!C12),Sheet1!C12),"") | D12: =IF(Sheet1!D12 <> "",IF(ISNUMBER(VALUE(Sheet1!D12)),VALUE(Sheet1!D12),Sheet1!D12),"") | E12: =IF(Sheet1!E12 <> "",IF(ISNUMBER(VALUE(Sheet1!E12)),VALUE(Sheet1!E12),Sheet1!E12),"") | F12: =IF(Sheet1!F12 <> "",IF(ISNUMBER(VALUE(Sheet1!F12)),VALUE(Sheet1!F12),Sheet1!F12),"") | G12: =IF(Sheet1!G12 <> "",IF(ISNUMBER(VALUE(Sheet1!G12)),VALUE(Sheet1!G12),Sheet1!G12),"") | H12: =IF(Sheet1!H12 <> "",IF(ISNUMBER(VALUE(Sheet1!H12)),VALUE(Sheet1!H12),Sheet1!H12),"") | ... BP12: =IF(Sheet1!BP12 <> "",IF(ISNUMBER(VALUE(Sheet1!BP12)),VALUE(Sheet1!BP12),Sheet1!BP12),"") | BQ12: =SUMIFS(G12:BP12,$G$9:$BP$9, $BO$9, G12:BP12,">0") | BR12: =COUNTIFS($G$9:$BP$9, $BO$9, G12:BP12,">0") | BS12: =SUMIFS(G12:BP12,$G$9:$BP$9, $BP$9, G12:BP12,">0") | BT12: =COUNTIFS($G$9:$BP$9, $BP$9, G12:BP12,">0") | BU12: =COUNTIF(G12:BP12,"Nghi") | BV12: =COUNTIFS($G$9:$BP$9, $BO$9, G12:BP12,$BX$8) | BW12: =COUNTIFS($G$9:$BP$9, $BP$9, G12:BP12,$BX$8) | BX12: =BV12+BW12
A13: =IF(Sheet1!A13 <> "",IF(ISNUMBER(VALUE(Sheet1!A13)),VALUE(Sheet1!A13),Sheet1!A13),"") | B13: =IF(Sheet1!B13 <> "",IF(ISNUMBER(VALUE(Sheet1!B13)),VALUE(Sheet1!B13),Sheet1!B13),"") | C13: =IF(Sheet1!C13 <> "",IF(ISNUMBER(VALUE(Sheet1!C13)),VALUE(Sheet1!C13),Sheet1!C13),"") | D13: =IF(Sheet1!D13 <> "",IF(ISNUMBER(VALUE(Sheet1!D13)),VALUE(Sheet1!D13),Sheet1!D13),"") | E13: =IF(Sheet1!E13 <> "",IF(ISNUMBER(VALUE(Sheet1!E13)),VALUE(Sheet1!E13),Sheet1!E13),"") | F13: =IF(Sheet1!F13 <> "",IF(ISNUMBER(VALUE(Sheet1!F13)),VALUE(Sheet1!F13),Sheet1!F13),"") | G13: =IF(Sheet1!G13 <> "",IF(ISNUMBER(VALUE(Sheet1!G13)),VALUE(Sheet1!G13),Sheet1!G13),"") | H13: =IF(Sheet1!H13 <> "",IF(ISNUMBER(VALUE(Sheet1!H13)),VALUE(Sheet1!H13),Sheet1!H13),"") | ... BP13: =IF(Sheet1!BP13 <> "",IF(ISNUMBER(VALUE(Sheet1!BP13)),VALUE(Sheet1!BP13),Sheet1!BP13),"") | BQ13: =SUMIFS(G13:BP13,$G$9:$BP$9, $BO$9, G13:BP13,">0") | BR13: =COUNTIFS($G$9:$BP$9, $BO$9, G13:BP13,">0") | BS13: =SUMIFS(G13:BP13,$G$9:$BP$9, $BP$9, G13:BP13,">0") | BT13: =COUNTIFS($G$9:$BP$9, $BP$9, G13:BP13,">0") | BU13: =COUNTIF(G13:BP13,"Nghi") | BV13: =COUNTIFS($G$9:$BP$9, $BO$9, G13:BP13,$BX$8) | BW13: =COUNTIFS($G$9:$BP$9, $BP$9, G13:BP13,$BX$8) | BX13: =BV13+BW13
A14: =IF(Sheet1!A14 <> "",IF(ISNUMBER(VALUE(Sheet1!A14)),VALUE(Sheet1!A14),Sheet1!A14),"") | B14: =IF(Sheet1!B14 <> "",IF(ISNUMBER(VALUE(Sheet1!B14)),VALUE(Sheet1!B14),Sheet1!B14),"") | C14: =IF(Sheet1!C14 <> "",IF(ISNUMBER(VALUE(Sheet1!C14)),VALUE(Sheet1!C14),Sheet1!C14),"") | D14: =IF(Sheet1!D14 <> "",IF(ISNUMBER(VALUE(Sheet1!D14)),VALUE(Sheet1!D14),Sheet1!D14),"") | E14: =IF(Sheet1!E14 <> "",IF(ISNUMBER(VALUE(Sheet1!E14)),VALUE(Sheet1!E14),Sheet1!E14),"") | F14: =IF(Sheet1!F14 <> "",IF(ISNUMBER(VALUE(Sheet1!F14)),VALUE(Sheet1!F14),Sheet1!F14),"") | G14: =IF(Sheet1!G14 <> "",IF(ISNUMBER(VALUE(Sheet1!G14)),VALUE(Sheet1!G14),Sheet1!G14),"") | H14: =IF(Sheet1!H14 <> "",IF(ISNUMBER(VALUE(Sheet1!H14)),VALUE(Sheet1!H14),Sheet1!H14),"") | ... BP14: =IF(Sheet1!BP14 <> "",IF(ISNUMBER(VALUE(Sheet1!BP14)),VALUE(Sheet1!BP14),Sheet1!BP14),"") | BQ14: =SUMIFS(G14:BP14,$G$9:$BP$9, $BO$9, G14:BP14,">0") | BR14: =COUNTIFS($G$9:$BP$9, $BO$9, G14:BP14,">0") | BS14: =SUMIFS(G14:BP14,$G$9:$BP$9, $BP$9, G14:BP14,">0") | BT14: =COUNTIFS($G$9:$BP$9, $BP$9, G14:BP14,">0") | BU14: =COUNTIF(G14:BP14,"Nghi") | BV14: =COUNTIFS($G$9:$BP$9, $BO$9, G14:BP14,$BX$8) | BW14: =COUNTIFS($G$9:$BP$9, $BP$9, G14:BP14,$BX$8) | BX14: =BV14+BW14
A15: =IF(Sheet1!A15 <> "",IF(ISNUMBER(VALUE(Sheet1!A15)),VALUE(Sheet1!A15),Sheet1!A15),"") | B15: =IF(Sheet1!B15 <> "",IF(ISNUMBER(VALUE(Sheet1!B15)),VALUE(Sheet1!B15),Sheet1!B15),"") | C15: =IF(Sheet1!C15 <> "",IF(ISNUMBER(VALUE(Sheet1!C15)),VALUE(Sheet1!C15),Sheet1!C15),"") | D15: =IF(Sheet1!D15 <> "",IF(ISNUMBER(VALUE(Sheet1!D15)),VALUE(Sheet1!D15),Sheet1!D15),"") | E15: =IF(Sheet1!E15 <> "",IF(ISNUMBER(VALUE(Sheet1!E15)),VALUE(Sheet1!E15),Sheet1!E15),"") | F15: =IF(Sheet1!F15 <> "",IF(ISNUMBER(VALUE(Sheet1!F15)),VALUE(Sheet1!F15),Sheet1!F15),"") | G15: =IF(Sheet1!G15 <> "",IF(ISNUMBER(VALUE(Sheet1!G15)),VALUE(Sheet1!G15),Sheet1!G15),"") | H15: =IF(Sheet1!H15 <> "",IF(ISNUMBER(VALUE(Sheet1!H15)),VALUE(Sheet1!H15),Sheet1!H15),"") | ... BP15: =IF(Sheet1!BP15 <> "",IF(ISNUMBER(VALUE(Sheet1!BP15)),VALUE(Sheet1!BP15),Sheet1!BP15),"") | BQ15: =SUMIFS(G15:BP15,$G$9:$BP$9, $BO$9, G15:BP15,">0") | BR15: =COUNTIFS($G$9:$BP$9, $BO$9, G15:BP15,">0") | BS15: =SUMIFS(G15:BP15,$G$9:$BP$9, $BP$9, G15:BP15,">0") | BT15: =COUNTIFS($G$9:$BP$9, $BP$9, G15:BP15,">0") | BU15: =COUNTIF(G15:BP15,"Nghi") | BV15: =COUNTIFS($G$9:$BP$9, $BO$9, G15:BP15,$BX$8) | BW15: =COUNTIFS($G$9:$BP$9, $BP$9, G15:BP15,$BX$8) | BX15: =BV15+BW15
A16: =IF(Sheet1!A16 <> "",IF(ISNUMBER(VALUE(Sheet1!A16)),VALUE(Sheet1!A16),Sheet1!A16),"") | B16: =IF(Sheet1!B16 <> "",IF(ISNUMBER(VALUE(Sheet1!B16)),VALUE(Sheet1!B16),Sheet1!B16),"") | C16: =IF(Sheet1!C16 <> "",IF(ISNUMBER(VALUE(Sheet1!C16)),VALUE(Sheet1!C16),Sheet1!C16),"") | D16: =IF(Sheet1!D16 <> "",IF(ISNUMBER(VALUE(Sheet1!D16)),VALUE(Sheet1!D16),Sheet1!D16),"") | E16: =IF(Sheet1!E16 <> "",IF(ISNUMBER(VALUE(Sheet1!E16)),VALUE(Sheet1!E16),Sheet1!E16),"") | F16: =IF(Sheet1!F16 <> "",IF(ISNUMBER(VALUE(Sheet1!F16)),VALUE(Sheet1!F16),Sheet1!F16),"") | G16: =IF(Sheet1!G16 <> "",IF(ISNUMBER(VALUE(Sheet1!G16)),VALUE(Sheet1!G16),Sheet1!G16),"") | H16: =IF(Sheet1!H16 <> "",IF(ISNUMBER(VALUE(Sheet1!H16)),VALUE(Sheet1!H16),Sheet1!H16),"") | ... BP16: =IF(Sheet1!BP16 <> "",IF(ISNUMBER(VALUE(Sheet1!BP16)),VALUE(Sheet1!BP16),Sheet1!BP16),"") | BQ16: =SUMIFS(G16:BP16,$G$9:$BP$9, $BO$9, G16:BP16,">0") | BR16: =COUNTIFS($G$9:$BP$9, $BO$9, G16:BP16,">0") | BS16: =SUMIFS(G16:BP16,$G$9:$BP$9, $BP$9, G16:BP16,">0") | BT16: =COUNTIFS($G$9:$BP$9, $BP$9, G16:BP16,">0") | BU16: =COUNTIF(G16:BP16,"Nghi") | BV16: =COUNTIFS($G$9:$BP$9, $BO$9, G16:BP16,$BX$8) | BW16: =COUNTIFS($G$9:$BP$9, $BP$9, G16:BP16,$BX$8) | BX16: =BV16+BW16
A17: =IF(Sheet1!A17 <> "",IF(ISNUMBER(VALUE(Sheet1!A17)),VALUE(Sheet1!A17),Sheet1!A17),"") | B17: =IF(Sheet1!B17 <> "",IF(ISNUMBER(VALUE(Sheet1!B17)),VALUE(Sheet1!B17),Sheet1!B17),"") | C17: =IF(Sheet1!C17 <> "",IF(ISNUMBER(VALUE(Sheet1!C17)),VALUE(Sheet1!C17),Sheet1!C17),"") | D17: =IF(Sheet1!D17 <> "",IF(ISNUMBER(VALUE(Sheet1!D17)),VALUE(Sheet1!D17),Sheet1!D17),"") | E17: =IF(Sheet1!E17 <> "",IF(ISNUMBER(VALUE(Sheet1!E17)),VALUE(Sheet1!E17),Sheet1!E17),"") | F17: =IF(Sheet1!F17 <> "",IF(ISNUMBER(VALUE(Sheet1!F17)),VALUE(Sheet1!F17),Sheet1!F17),"") | G17: =IF(Sheet1!G17 <> "",IF(ISNUMBER(VALUE(Sheet1!G17)),VALUE(Sheet1!G17),Sheet1!G17),"") | H17: =IF(Sheet1!H17 <> "",IF(ISNUMBER(VALUE(Sheet1!H17)),VALUE(Sheet1!H17),Sheet1!H17),"") | ... BP17: =IF(Sheet1!BP17 <> "",IF(ISNUMBER(VALUE(Sheet1!BP17)),VALUE(Sheet1!BP17),Sheet1!BP17),"") | BQ17: =SUMIFS(G17:BP17,$G$9:$BP$9, $BO$9, G17:BP17,">0") | BR17: =COUNTIFS($G$9:$BP$9, $BO$9, G17:BP17,">0") | BS17: =SUMIFS(G17:BP17,$G$9:$BP$9, $BP$9, G17:BP17,">0") | BT17: =COUNTIFS($G$9:$BP$9, $BP$9, G17:BP17,">0") | BU17: =COUNTIF(G17:BP17,"Nghi") | BV17: =COUNTIFS($G$9:$BP$9, $BO$9, G17:BP17,$BX$8) | BW17: =COUNTIFS($G$9:$BP$9, $BP$9, G17:BP17,$BX$8) | BX17: =BV17+BW17
A18: =IF(Sheet1!A18 <> "",IF(ISNUMBER(VALUE(Sheet1!A18)),VALUE(Sheet1!A18),Sheet1!A18),"") | B18: =IF(Sheet1!B18 <> "",IF(ISNUMBER(VALUE(Sheet1!B18)),VALUE(Sheet1!B18),Sheet1!B18),"") | C18: =IF(Sheet1!C18 <> "",IF(ISNUMBER(VALUE(Sheet1!C18)),VALUE(Sheet1!C18),Sheet1!C18),"") | D18: =IF(Sheet1!D18 <> "",IF(ISNUMBER(VALUE(Sheet1!D18)),VALUE(Sheet1!D18),Sheet1!D18),"") | E18: =IF(Sheet1!E18 <> "",IF(ISNUMBER(VALUE(Sheet1!E18)),VALUE(Sheet1!E18),Sheet1!E18),"") | F18: =IF(Sheet1!F18 <> "",IF(ISNUMBER(VALUE(Sheet1!F18)),VALUE(Sheet1!F18),Sheet1!F18),"") | G18: =IF(Sheet1!G18 <> "",IF(ISNUMBER(VALUE(Sheet1!G18)),VALUE(Sheet1!G18),Sheet1!G18),"") | H18: =IF(Sheet1!H18 <> "",IF(ISNUMBER(VALUE(Sheet1!H18)),VALUE(Sheet1!H18),Sheet1!H18),"") | ... BP18: =IF(Sheet1!BP18 <> "",IF(ISNUMBER(VALUE(Sheet1!BP18)),VALUE(Sheet1!BP18),Sheet1!BP18),"") | BQ18: =SUMIFS(G18:BP18,$G$9:$BP$9, $BO$9, G18:BP18,">0") | BR18: =COUNTIFS($G$9:$BP$9, $BO$9, G18:BP18,">0") | BS18: =SUMIFS(G18:BP18,$G$9:$BP$9, $BP$9, G18:BP18,">0") | BT18: =COUNTIFS($G$9:$BP$9, $BP$9, G18:BP18,">0") | BU18: =COUNTIF(G18:BP18,"Nghi") | BV18: =COUNTIFS($G$9:$BP$9, $BO$9, G18:BP18,$BX$8) | BW18: =COUNTIFS($G$9:$BP$9, $BP$9, G18:BP18,$BX$8) | BX18: =BV18+BW18
A19: =IF(Sheet1!A19 <> "",IF(ISNUMBER(VALUE(Sheet1!A19)),VALUE(Sheet1!A19),Sheet1!A19),"") | B19: =IF(Sheet1!B19 <> "",IF(ISNUMBER(VALUE(Sheet1!B19)),VALUE(Sheet1!B19),Sheet1!B19),"") | C19: =IF(Sheet1!C19 <> "",IF(ISNUMBER(VALUE(Sheet1!C19)),VALUE(Sheet1!C19),Sheet1!C19),"") | D19: =IF(Sheet1!D19 <> "",IF(ISNUMBER(VALUE(Sheet1!D19)),VALUE(Sheet1!D19),Sheet1!D19),"") | E19: =IF(Sheet1!E19 <> "",IF(ISNUMBER(VALUE(Sheet1!E19)),VALUE(Sheet1!E19),Sheet1!E19),"") | F19: =IF(Sheet1!F19 <> "",IF(ISNUMBER(VALUE(Sheet1!F19)),VALUE(Sheet1!F19),Sheet1!F19),"") | G19: =IF(Sheet1!G19 <> "",IF(ISNUMBER(VALUE(Sheet1!G19)),VALUE(Sheet1!G19),Sheet1!G19),"") | H19: =IF(Sheet1!H19 <> "",IF(ISNUMBER(VALUE(Sheet1!H19)),VALUE(Sheet1!H19),Sheet1!H19),"") | ... BP19: =IF(Sheet1!BP19 <> "",IF(ISNUMBER(VALUE(Sheet1!BP19)),VALUE(Sheet1!BP19),Sheet1!BP19),"") | BQ19: =SUMIFS(G19:BP19,$G$9:$BP$9, $BO$9, G19:BP19,">0") | BR19: =COUNTIFS($G$9:$BP$9, $BO$9, G19:BP19,">0") | BS19: =SUMIFS(G19:BP19,$G$9:$BP$9, $BP$9, G19:BP19,">0") | BT19: =COUNTIFS($G$9:$BP$9, $BP$9, G19:BP19,">0") | BU19: =COUNTIF(G19:BP19,"Nghi") | BV19: =COUNTIFS($G$9:$BP$9, $BO$9, G19:BP19,$BX$8) | BW19: =COUNTIFS($G$9:$BP$9, $BP$9, G19:BP19,$BX$8) | BX19: =BV19+BW19
A20: =IF(Sheet1!A20 <> "",IF(ISNUMBER(VALUE(Sheet1!A20)),VALUE(Sheet1!A20),Sheet1!A20),"") | B20: =IF(Sheet1!B20 <> "",IF(ISNUMBER(VALUE(Sheet1!B20)),VALUE(Sheet1!B20),Sheet1!B20),"") | C20: =IF(Sheet1!C20 <> "",IF(ISNUMBER(VALUE(Sheet1!C20)),VALUE(Sheet1!C20),Sheet1!C20),"") | D20: =IF(Sheet1!D20 <> "",IF(ISNUMBER(VALUE(Sheet1!D20)),VALUE(Sheet1!D20),Sheet1!D20),"") | E20: =IF(Sheet1!E20 <> "",IF(ISNUMBER(VALUE(Sheet1!E20)),VALUE(Sheet1!E20),Sheet1!E20),"") | F20: =IF(Sheet1!F20 <> "",IF(ISNUMBER(VALUE(Sheet1!F20)),VALUE(Sheet1!F20),Sheet1!F20),"") | G20: =IF(Sheet1!G20 <> "",IF(ISNUMBER(VALUE(Sheet1!G20)),VALUE(Sheet1!G20),Sheet1!G20),"") | H20: =IF(Sheet1!H20 <> "",IF(ISNUMBER(VALUE(Sheet1!H20)),VALUE(Sheet1!H20),Sheet1!H20),"") | ... BP20: =IF(Sheet1!BP20 <> "",IF(ISNUMBER(VALUE(Sheet1!BP20)),VALUE(Sheet1!BP20),Sheet1!BP20),"") | BQ20: =SUMIFS(G20:BP20,$G$9:$BP$9, $BO$9, G20:BP20,">0") | BR20: =COUNTIFS($G$9:$BP$9, $BO$9, G20:BP20,">0") | BS20: =SUMIFS(G20:BP20,$G$9:$BP$9, $BP$9, G20:BP20,">0") | BT20: =COUNTIFS($G$9:$BP$9, $BP$9, G20:BP20,">0") | BU20: =COUNTIF(G20:BP20,"Nghi") | BV20: =COUNTIFS($G$9:$BP$9, $BO$9, G20:BP20,$BX$8) | BW20: =COUNTIFS($G$9:$BP$9, $BP$9, G20:BP20,$BX$8) | BX20: =BV20+BW20
A21: =IF(Sheet1!A21 <> "",IF(ISNUMBER(VALUE(Sheet1!A21)),VALUE(Sheet1!A21),Sheet1!A21),"") | B21: =IF(Sheet1!B21 <> "",IF(ISNUMBER(VALUE(Sheet1!B21)),VALUE(Sheet1!B21),Sheet1!B21),"") | C21: =IF(Sheet1!C21 <> "",IF(ISNUMBER(VALUE(Sheet1!C21)),VALUE(Sheet1!C21),Sheet1!C21),"") | D21: =IF(Sheet1!D21 <> "",IF(ISNUMBER(VALUE(Sheet1!D21)),VALUE(Sheet1!D21),Sheet1!D21),"") | E21: =IF(Sheet1!E21 <> "",IF(ISNUMBER(VALUE(Sheet1!E21)),VALUE(Sheet1!E21),Sheet1!E21),"") | F21: =IF(Sheet1!F21 <> "",IF(ISNUMBER(VALUE(Sheet1!F21)),VALUE(Sheet1!F21),Sheet1!F21),"") | G21: =IF(Sheet1!G21 <> "",IF(ISNUMBER(VALUE(Sheet1!G21)),VALUE(Sheet1!G21),Sheet1!G21),"") | H21: =IF(Sheet1!H21 <> "",IF(ISNUMBER(VALUE(Sheet1!H21)),VALUE(Sheet1!H21),Sheet1!H21),"") | ... BP21: =IF(Sheet1!BP21 <> "",IF(ISNUMBER(VALUE(Sheet1!BP21)),VALUE(Sheet1!BP21),Sheet1!BP21),"") | BQ21: =SUMIFS(G21:BP21,$G$9:$BP$9, $BO$9, G21:BP21,">0") | BR21: =COUNTIFS($G$9:$BP$9, $BO$9, G21:BP21,">0") | BS21: =SUMIFS(G21:BP21,$G$9:$BP$9, $BP$9, G21:BP21,">0") | BT21: =COUNTIFS($G$9:$BP$9, $BP$9, G21:BP21,">0") | BU21: =COUNTIF(G21:BP21,"Nghi") | BV21: =COUNTIFS($G$9:$BP$9, $BO$9, G21:BP21,$BX$8) | BW21: =COUNTIFS($G$9:$BP$9, $BP$9, G21:BP21,$BX$8) | BX21: =BV21+BW21
A22: =IF(Sheet1!A22 <> "",IF(ISNUMBER(VALUE(Sheet1!A22)),VALUE(Sheet1!A22),Sheet1!A22),"") | B22: =IF(Sheet1!B22 <> "",IF(ISNUMBER(VALUE(Sheet1!B22)),VALUE(Sheet1!B22),Sheet1!B22),"") | C22: =IF(Sheet1!C22 <> "",IF(ISNUMBER(VALUE(Sheet1!C22)),VALUE(Sheet1!C22),Sheet1!C22),"") | D22: =IF(Sheet1!D22 <> "",IF(ISNUMBER(VALUE(Sheet1!D22)),VALUE(Sheet1!D22),Sheet1!D22),"") | E22: =IF(Sheet1!E22 <> "",IF(ISNUMBER(VALUE(Sheet1!E22)),VALUE(Sheet1!E22),Sheet1!E22),"") | F22: =IF(Sheet1!F22 <> "",IF(ISNUMBER(VALUE(Sheet1!F22)),VALUE(Sheet1!F22),Sheet1!F22),"") | G22: =IF(Sheet1!G22 <> "",IF(ISNUMBER(VALUE(Sheet1!G22)),VALUE(Sheet1!G22),Sheet1!G22),"") | H22: =IF(Sheet1!H22 <> "",IF(ISNUMBER(VALUE(Sheet1!H22)),VALUE(Sheet1!H22),Sheet1!H22),"") | ... BP22: =IF(Sheet1!BP22 <> "",IF(ISNUMBER(VALUE(Sheet1!BP22)),VALUE(Sheet1!BP22),Sheet1!BP22),"") | BQ22: =SUMIFS(G22:BP22,$G$9:$BP$9, $BO$9, G22:BP22,">0") | BR22: =COUNTIFS($G$9:$BP$9, $BO$9, G22:BP22,">0") | BS22: =SUMIFS(G22:BP22,$G$9:$BP$9, $BP$9, G22:BP22,">0") | BT22: =COUNTIFS($G$9:$BP$9, $BP$9, G22:BP22,">0") | BU22: =COUNTIF(G22:BP22,"Nghi") | BV22: =COUNTIFS($G$9:$BP$9, $BO$9, G22:BP22,$BX$8) | BW22: =COUNTIFS($G$9:$BP$9, $BP$9, G22:BP22,$BX$8) | BX22: =BV22+BW22
... A1478: =IF(Sheet1!A1478 <> "",IF(ISNUMBER(VALUE(Sheet1!A1478)),VALUE(Sheet1!A1478),Sheet1!A1478),"") | B1478: =IF(Sheet1!B1478 <> "",IF(ISNUMBER(VALUE(Sheet1!B1478)),VALUE(Sheet1!B1478),Sheet1!B1478),"") | C1478: =IF(Sheet1!C1478 <> "",IF(ISNUMBER(VALUE(Sheet1!C1478)),VALUE(Sheet1!C1478),Sheet1!C1478),"") | D1478: =IF(Sheet1!D1478 <> "",IF(ISNUMBER(VALUE(Sheet1!D1478)),VALUE(Sheet1!D1478),Sheet1!D1478),"") | E1478: =IF(Sheet1!E1478 <> "",IF(ISNUMBER(VALUE(Sheet1!E1478)),VALUE(Sheet1!E1478),Sheet1!E1478),"") | F1478: =IF(Sheet1!F1478 <> "",IF(ISNUMBER(VALUE(Sheet1!F1478)),VALUE(Sheet1!F1478),Sheet1!F1478),"") | G1478: =IF(Sheet1!G1478 <> "",IF(ISNUMBER(VALUE(Sheet1!G1478)),VALUE(Sheet1!G1478),Sheet1!G1478),"") | H1478: =IF(Sheet1!H1478 <> "",IF(ISNUMBER(VALUE(Sheet1!H1478)),VALUE(Sheet1!H1478),Sheet1!H1478),"") | ... BP1478: =IF(Sheet1!BP1478 <> "",IF(ISNUMBER(VALUE(Sheet1!BP1478)),VALUE(Sheet1!BP1478),Sheet1!BP1478),"") | BQ1478: =SUMIFS(G1478:BP1478,$G$9:$BP$9, $BO$9, G1478:BP1478,">0") | BR1478: =COUNTIFS($G$9:$BP$9, $BO$9, G1478:BP1478,">0") | BS1478: =SUMIFS(G1478:BP1478,$G$9:$BP$9, $BP$9, G1478:BP1478,">0") | BT1478: =COUNTIFS($G$9:$BP$9, $BP$9, G1478:BP1478,">0") | BU1478: =COUNTIF(G1478:BP1478,"Nghi") | BV1478: =COUNTIFS($G$9:$BP$9, $BO$9, G1478:BP1478,$BX$8) | BW1478: =COUNTIFS($G$9:$BP$9, $BP$9, G1478:BP1478,$BX$8) | BX1478: =BV1478+BW1478
